Watching for file changes with StatReloader
Job with id myLucky.views.my_job already in jobstore. I'll refresh it
Watching for file changes with StatReloader
Job with id myLucky.views.my_job already in jobstore. I'll refresh it
Exception during getting jobs
Traceback (most recent call last):
  File "/Users/jinhui/PycharmProjects/Lucky/venv/lib/python3.7/site-packages/django/db/backends/utils.py", line 86, in _execute
    return self.cursor.execute(sql, params)
  File "/Users/jinhui/PycharmProjects/Lucky/venv/lib/python3.7/site-packages/django/db/backends/mysql/base.py", line 74, in execute
    return self.cursor.execute(query, args)
  File "/Users/jinhui/PycharmProjects/Lucky/venv/lib/python3.7/site-packages/pymysql/cursors.py", line 170, in execute
    result = self._query(query)
  File "/Users/jinhui/PycharmProjects/Lucky/venv/lib/python3.7/site-packages/pymysql/cursors.py", line 328, in _query
    conn.query(q)
  File "/Users/jinhui/PycharmProjects/Lucky/venv/lib/python3.7/site-packages/pymysql/connections.py", line 517, in query
    self._affected_rows = self._read_query_result(unbuffered=unbuffered)
  File "/Users/jinhui/PycharmProjects/Lucky/venv/lib/python3.7/site-packages/pymysql/connections.py", line 732, in _read_query_result
    result.read()
  File "/Users/jinhui/PycharmProjects/Lucky/venv/lib/python3.7/site-packages/pymysql/connections.py", line 1075, in read
    first_packet = self.connection._read_packet()
  File "/Users/jinhui/PycharmProjects/Lucky/venv/lib/python3.7/site-packages/pymysql/connections.py", line 684, in _read_packet
    packet.check_error()
  File "/Users/jinhui/PycharmProjects/Lucky/venv/lib/python3.7/site-packages/pymysql/protocol.py", line 220, in check_error
    err.raise_mysql_exception(self._data)
  File "/Users/jinhui/PycharmProjects/Lucky/venv/lib/python3.7/site-packages/pymysql/err.py", line 109, in raise_mysql_exception
    raise errorclass(errno, errval)
pymysql.err.InternalError: (1053, 'Server shutdown in progress')

The above exception was the direct cause of the following exception:

Traceback (most recent call last):
  File "/Users/jinhui/PycharmProjects/Lucky/venv/lib/python3.7/site-packages/django_apscheduler/jobstores.py", line 68, in get_due_jobs
    out = self._get_jobs(next_run_time__lte=serialize_dt(now))
  File "/Users/jinhui/PycharmProjects/Lucky/venv/lib/python3.7/site-packages/django_apscheduler/jobstores.py", line 153, in _get_jobs
    for job_id, job_state in job_states:
  File "/Users/jinhui/PycharmProjects/Lucky/venv/lib/python3.7/site-packages/django/db/models/query.py", line 276, in __iter__
    self._fetch_all()
  File "/Users/jinhui/PycharmProjects/Lucky/venv/lib/python3.7/site-packages/django/db/models/query.py", line 1261, in _fetch_all
    self._result_cache = list(self._iterable_class(self))
  File "/Users/jinhui/PycharmProjects/Lucky/venv/lib/python3.7/site-packages/django/db/models/query.py", line 146, in __iter__
    return compiler.results_iter(tuple_expected=True, chunked_fetch=self.chunked_fetch, chunk_size=self.chunk_size)
  File "/Users/jinhui/PycharmProjects/Lucky/venv/lib/python3.7/site-packages/django/db/models/sql/compiler.py", line 1096, in results_iter
    results = self.execute_sql(MULTI, chunked_fetch=chunked_fetch, chunk_size=chunk_size)
  File "/Users/jinhui/PycharmProjects/Lucky/venv/lib/python3.7/site-packages/django/db/models/sql/compiler.py", line 1144, in execute_sql
    cursor.execute(sql, params)
  File "/Users/jinhui/PycharmProjects/Lucky/venv/lib/python3.7/site-packages/django/db/backends/utils.py", line 100, in execute
    return super().execute(sql, params)
  File "/Users/jinhui/PycharmProjects/Lucky/venv/lib/python3.7/site-packages/django/db/backends/utils.py", line 68, in execute
    return self._execute_with_wrappers(sql, params, many=False, executor=self._execute)
  File "/Users/jinhui/PycharmProjects/Lucky/venv/lib/python3.7/site-packages/django/db/backends/utils.py", line 77, in _execute_with_wrappers
    return executor(sql, params, many, context)
  File "/Users/jinhui/PycharmProjects/Lucky/venv/lib/python3.7/site-packages/django/db/backends/utils.py", line 86, in _execute
    return self.cursor.execute(sql, params)
  File "/Users/jinhui/PycharmProjects/Lucky/venv/lib/python3.7/site-packages/django/db/utils.py", line 90, in __exit__
    raise dj_exc_value.with_traceback(traceback) from exc_value
  File "/Users/jinhui/PycharmProjects/Lucky/venv/lib/python3.7/site-packages/django/db/backends/utils.py", line 86, in _execute
    return self.cursor.execute(sql, params)
  File "/Users/jinhui/PycharmProjects/Lucky/venv/lib/python3.7/site-packages/django/db/backends/mysql/base.py", line 74, in execute
    return self.cursor.execute(query, args)
  File "/Users/jinhui/PycharmProjects/Lucky/venv/lib/python3.7/site-packages/pymysql/cursors.py", line 170, in execute
    result = self._query(query)
  File "/Users/jinhui/PycharmProjects/Lucky/venv/lib/python3.7/site-packages/pymysql/cursors.py", line 328, in _query
    conn.query(q)
  File "/Users/jinhui/PycharmProjects/Lucky/venv/lib/python3.7/site-packages/pymysql/connections.py", line 517, in query
    self._affected_rows = self._read_query_result(unbuffered=unbuffered)
  File "/Users/jinhui/PycharmProjects/Lucky/venv/lib/python3.7/site-packages/pymysql/connections.py", line 732, in _read_query_result
    result.read()
  File "/Users/jinhui/PycharmProjects/Lucky/venv/lib/python3.7/site-packages/pymysql/connections.py", line 1075, in read
    first_packet = self.connection._read_packet()
  File "/Users/jinhui/PycharmProjects/Lucky/venv/lib/python3.7/site-packages/pymysql/connections.py", line 684, in _read_packet
    packet.check_error()
  File "/Users/jinhui/PycharmProjects/Lucky/venv/lib/python3.7/site-packages/pymysql/protocol.py", line 220, in check_error
    err.raise_mysql_exception(self._data)
  File "/Users/jinhui/PycharmProjects/Lucky/venv/lib/python3.7/site-packages/pymysql/err.py", line 109, in raise_mysql_exception
    raise errorclass(errno, errval)
django.db.utils.InternalError: (1053, 'Server shutdown in progress')
Exception during get_next_run_time for jobs
Traceback (most recent call last):
  File "/Users/jinhui/PycharmProjects/Lucky/venv/lib/python3.7/site-packages/pymysql/connections.py", line 691, in _read_bytes
    data = self._rfile.read(num_bytes)
  File "/Library/Frameworks/Python.framework/Versions/3.7/lib/python3.7/socket.py", line 589, in readinto
    return self._sock.recv_into(b)
ConnectionResetError: [Errno 54] Connection reset by peer

During handling of the above exception, another exception occurred:

Traceback (most recent call last):
  File "/Users/jinhui/PycharmProjects/Lucky/venv/lib/python3.7/site-packages/django/db/backends/utils.py", line 86, in _execute
    return self.cursor.execute(sql, params)
  File "/Users/jinhui/PycharmProjects/Lucky/venv/lib/python3.7/site-packages/django/db/backends/mysql/base.py", line 74, in execute
    return self.cursor.execute(query, args)
  File "/Users/jinhui/PycharmProjects/Lucky/venv/lib/python3.7/site-packages/pymysql/cursors.py", line 170, in execute
    result = self._query(query)
  File "/Users/jinhui/PycharmProjects/Lucky/venv/lib/python3.7/site-packages/pymysql/cursors.py", line 328, in _query
    conn.query(q)
  File "/Users/jinhui/PycharmProjects/Lucky/venv/lib/python3.7/site-packages/pymysql/connections.py", line 517, in query
    self._affected_rows = self._read_query_result(unbuffered=unbuffered)
  File "/Users/jinhui/PycharmProjects/Lucky/venv/lib/python3.7/site-packages/pymysql/connections.py", line 732, in _read_query_result
    result.read()
  File "/Users/jinhui/PycharmProjects/Lucky/venv/lib/python3.7/site-packages/pymysql/connections.py", line 1075, in read
    first_packet = self.connection._read_packet()
  File "/Users/jinhui/PycharmProjects/Lucky/venv/lib/python3.7/site-packages/pymysql/connections.py", line 657, in _read_packet
    packet_header = self._read_bytes(4)
  File "/Users/jinhui/PycharmProjects/Lucky/venv/lib/python3.7/site-packages/pymysql/connections.py", line 699, in _read_bytes
    "Lost connection to MySQL server during query (%s)" % (e,))
pymysql.err.OperationalError: (2013, 'Lost connection to MySQL server during query ([Errno 54] Connection reset by peer)')

The above exception was the direct cause of the following exception:

Traceback (most recent call last):
  File "/Users/jinhui/PycharmProjects/Lucky/venv/lib/python3.7/site-packages/django_apscheduler/jobstores.py", line 78, in get_next_run_time
    return deserialize_dt(DjangoJob.objects.filter(next_run_time__isnull=False).earliest('next_run_time').next_run_time)
  File "/Users/jinhui/PycharmProjects/Lucky/venv/lib/python3.7/site-packages/django/db/models/query.py", line 657, in earliest
    return self._earliest(*fields)
  File "/Users/jinhui/PycharmProjects/Lucky/venv/lib/python3.7/site-packages/django/db/models/query.py", line 654, in _earliest
    return obj.get()
  File "/Users/jinhui/PycharmProjects/Lucky/venv/lib/python3.7/site-packages/django/db/models/query.py", line 411, in get
    num = len(clone)
  File "/Users/jinhui/PycharmProjects/Lucky/venv/lib/python3.7/site-packages/django/db/models/query.py", line 258, in __len__
    self._fetch_all()
  File "/Users/jinhui/PycharmProjects/Lucky/venv/lib/python3.7/site-packages/django/db/models/query.py", line 1261, in _fetch_all
    self._result_cache = list(self._iterable_class(self))
  File "/Users/jinhui/PycharmProjects/Lucky/venv/lib/python3.7/site-packages/django/db/models/query.py", line 57, in __iter__
    results = compiler.execute_sql(chunked_fetch=self.chunked_fetch, chunk_size=self.chunk_size)
  File "/Users/jinhui/PycharmProjects/Lucky/venv/lib/python3.7/site-packages/django/db/models/sql/compiler.py", line 1144, in execute_sql
    cursor.execute(sql, params)
  File "/Users/jinhui/PycharmProjects/Lucky/venv/lib/python3.7/site-packages/django/db/backends/utils.py", line 100, in execute
    return super().execute(sql, params)
  File "/Users/jinhui/PycharmProjects/Lucky/venv/lib/python3.7/site-packages/django/db/backends/utils.py", line 68, in execute
    return self._execute_with_wrappers(sql, params, many=False, executor=self._execute)
  File "/Users/jinhui/PycharmProjects/Lucky/venv/lib/python3.7/site-packages/django/db/backends/utils.py", line 77, in _execute_with_wrappers
    return executor(sql, params, many, context)
  File "/Users/jinhui/PycharmProjects/Lucky/venv/lib/python3.7/site-packages/django/db/backends/utils.py", line 86, in _execute
    return self.cursor.execute(sql, params)
  File "/Users/jinhui/PycharmProjects/Lucky/venv/lib/python3.7/site-packages/django/db/utils.py", line 90, in __exit__
    raise dj_exc_value.with_traceback(traceback) from exc_value
  File "/Users/jinhui/PycharmProjects/Lucky/venv/lib/python3.7/site-packages/django/db/backends/utils.py", line 86, in _execute
    return self.cursor.execute(sql, params)
  File "/Users/jinhui/PycharmProjects/Lucky/venv/lib/python3.7/site-packages/django/db/backends/mysql/base.py", line 74, in execute
    return self.cursor.execute(query, args)
  File "/Users/jinhui/PycharmProjects/Lucky/venv/lib/python3.7/site-packages/pymysql/cursors.py", line 170, in execute
    result = self._query(query)
  File "/Users/jinhui/PycharmProjects/Lucky/venv/lib/python3.7/site-packages/pymysql/cursors.py", line 328, in _query
    conn.query(q)
  File "/Users/jinhui/PycharmProjects/Lucky/venv/lib/python3.7/site-packages/pymysql/connections.py", line 517, in query
    self._affected_rows = self._read_query_result(unbuffered=unbuffered)
  File "/Users/jinhui/PycharmProjects/Lucky/venv/lib/python3.7/site-packages/pymysql/connections.py", line 732, in _read_query_result
    result.read()
  File "/Users/jinhui/PycharmProjects/Lucky/venv/lib/python3.7/site-packages/pymysql/connections.py", line 1075, in read
    first_packet = self.connection._read_packet()
  File "/Users/jinhui/PycharmProjects/Lucky/venv/lib/python3.7/site-packages/pymysql/connections.py", line 657, in _read_packet
    packet_header = self._read_bytes(4)
  File "/Users/jinhui/PycharmProjects/Lucky/venv/lib/python3.7/site-packages/pymysql/connections.py", line 699, in _read_bytes
    "Lost connection to MySQL server during query (%s)" % (e,))
django.db.utils.OperationalError: (2013, 'Lost connection to MySQL server during query ([Errno 54] Connection reset by peer)')
